<mujoco>
	<asset>
		<material name="red"   rgba="1 0 0 1"/>
		<material name="green" rgba="0 1 0 1"/>
		<material name="blue"  rgba="0 0 1 1"/>
		<material name="white" rgba="1 1 1 1"/>
		<material name="gray"  rgba=".5 .5 .5 1"/>
	</asset>

    <worldbody>
        <light diffuse=".5 .5 .5" pos="0 0 10" dir="0 0 -1"/>
        <geom type="plane" size="2 2 0.1" rgba="1 1 1 1"/>

        <body name="link 0" pos="0.5 0 0.1" euler="0 90 0">
            <joint name="joint 0" type="hinge" axis="-1 0 0" pos="0 0 -0.5"/>
            <geom name="geom link 0" type="cylinder" size="0.05 0.5" material="red"/>
            <body name="link 1" pos="0 0 1.0" euler="0 0 0">
                <joint name="joint 1" type="hinge" axis="-1 0 0" pos="0 0 -0.5"/>
                <geom name="geom link 1" type="cylinder" size="0.05 0.5" material="red"/>
                <site name="tip" size="0.1" pos="0 0 0.5"/>
            </body>
        </body>

        <body name="link 0 shade" pos="0.5 0 0.1" euler="0 90 0">
            <joint name="joint 0 shade" type="hinge" axis="-1 0 0" pos="0 0 -0.5"/>
            <geom name="geom link 0 shade" type="cylinder" size="0.05 0.5" material="green"/>
            <body name="link 1 shade" pos="0 0 1.0" euler="0 0 0">
                <joint name="joint 1 shade" type="hinge" axis="-1 0 0" pos="0 0 -0.5"/>
                <geom name="geom link 1 shade" type="cylinder" size="0.05 0.5" material="green"/>
            </body>
        </body>

        <body name="obstacle 0">
            <geom name="geom obstacle 0" type="sphere" size="0.05" pos="1.1 0.0 0.1" material="blue"/>
        </body>
        <body name="obstacle 1">
            <geom name="geom obstacle 1" type="sphere" size="0.05" pos="0.7778174593052024 0.7778174593052023 0.1" material="blue"/>
        </body>
        <body name="obstacle 2">
            <geom name="geom obstacle 2" type="sphere" size="0.05" pos="6.735557395310444e-17 1.1 0.1" material="blue"/>
        </body>
        <body name="obstacle 3">
            <geom name="geom obstacle 3" type="sphere" size="0.05" pos="-0.7778174593052023 0.7778174593052024 0.1" material="blue"/>
        </body>
        <body name="obstacle 4">
            <geom name="geom obstacle 4" type="sphere" size="0.05" pos="-1.1 1.3471114790620887e-16 0.1" material="blue"/>
        </body>
        <body name="obstacle 5">
            <geom name="geom obstacle 5" type="sphere" size="0.05" pos="-0.7778174593052025 -0.7778174593052023 0.1" material="blue"/>
        </body>
        <body name="obstacle 6">
            <geom name="geom obstacle 6" type="sphere" size="0.05" pos="-2.0206672185931328e-16 -1.1 0.1" material="blue"/>
        </body>
        <body name="obstacle 7">
            <geom name="geom obstacle 7" type="sphere" size="0.05" pos="0.7778174593052022 -0.7778174593052025 0.1" material="blue"/>
        </body>

    </worldbody>

    <contact>
        <exclude body1="link 0 shade" body2="link 1 shade"/>
        <exclude body1="link 0 shade" body2="link 0"/>
        <exclude body1="link 0 shade" body2="link 1"/>
        <exclude body1="link 1 shade" body2="link 0"/>
        <exclude body1="link 1 shade" body2="link 1"/>
        <exclude body1="link 0 shade" body2="obstacle 0"/>
        <exclude body1="link 0 shade" body2="obstacle 1"/>
        <exclude body1="link 0 shade" body2="obstacle 2"/>
        <exclude body1="link 0 shade" body2="obstacle 3"/>
        <exclude body1="link 0 shade" body2="obstacle 4"/>
        <exclude body1="link 0 shade" body2="obstacle 5"/>
        <exclude body1="link 0 shade" body2="obstacle 6"/>
        <exclude body1="link 0 shade" body2="obstacle 7"/>
        <exclude body1="link 1 shade" body2="obstacle 0"/>
        <exclude body1="link 1 shade" body2="obstacle 1"/>
        <exclude body1="link 1 shade" body2="obstacle 2"/>
        <exclude body1="link 1 shade" body2="obstacle 3"/>
        <exclude body1="link 1 shade" body2="obstacle 4"/>
        <exclude body1="link 1 shade" body2="obstacle 5"/>
        <exclude body1="link 1 shade" body2="obstacle 6"/>
        <exclude body1="link 1 shade" body2="obstacle 7"/>
    </contact>

    <sensor>
      <framepos objtype="site" objname="tip"/>
    </sensor>
</mujoco>
