<mujoco>
	<asset>
		<material name="red"   rgba="1 0 0 1"/>
		<material name="green" rgba="0 1 0 1"/>
		<material name="blue"  rgba="0 0 1 1"/>
		<material name="white" rgba="1 1 1 1"/>
		<material name="gray"  rgba=".5 .5 .5 1"/>
	</asset>

    <worldbody>
        <light diffuse=".5 .5 .5" pos="0 0 10" dir="0 0 -1"/>
        <geom type="plane" size="2 2 0.1" rgba="1 1 1 1"/>

        <body name="link 0" pos="0.5 0 0.1" euler="0 90 0">
            <joint name="joint 0" type="hinge" axis="-1 0 0" pos="0 0 -0.5"/>
            <geom name="geom link 0" type="cylinder" size="0.05 0.5" material="red"/>
            <body name="link 1" pos="0 0 1.0" euler="0 0 0">
                <joint name="joint 1" type="hinge" axis="-1 0 0" pos="0 0 -0.5"/>
                <geom name="geom link 1" type="cylinder" size="0.05 0.5" material="red"/>
                <site name="tip" size="0.1" pos="0 0 0.5"/>
            </body>
        </body>

        <body name="link 0 shade" pos="0.5 0 0.1" euler="0 90 0">
            <joint name="joint 0 shade" type="hinge" axis="-1 0 0" pos="0 0 -0.5"/>
            <geom name="geom link 0 shade" type="cylinder" size="0.05 0.5" material="green"/>
            <body name="link 1 shade" pos="0 0 1.0" euler="0 0 0">
                <joint name="joint 1 shade" type="hinge" axis="-1 0 0" pos="0 0 -0.5"/>
                <geom name="geom link 1 shade" type="cylinder" size="0.05 0.5" material="green"/>
            </body>
        </body>

        <body name="obstacle 0">
            <geom name="geom obstacle 0" type="box" size="0.19424149257733284 0.13139969321467654 0.1" pos="1.216294562138744 0.25948255469938 0.1" material="blue"/>
        </body>
        <body name="obstacle 1">
            <geom name="geom obstacle 1" type="box" size="0.22234641782136644 0.15792600764007167 0.1" pos="-1.0607541936228446 -0.5144505756406965 0.1" material="blue"/>
        </body>
        <body name="obstacle 2">
            <geom name="geom obstacle 2" type="box" size="0.20433238741441645 0.21778747983290256 0.1" pos="-1.2792747053227727 0.5253611144012202 0.1" material="blue"/>
        </body>
        <body name="obstacle 3">
            <geom name="geom obstacle 3" type="box" size="0.15908562361336712 0.20077803817302745 0.1" pos="-1.3978006950546744 -0.43128998441569966 0.1" material="blue"/>
        </body>
        <body name="obstacle 4">
            <geom name="geom obstacle 4" type="box" size="0.1446898632081366 0.15719518369387056 0.1" pos="1.170557367367779 -0.10378527148189098 0.1" material="blue"/>
        </body>
        <body name="obstacle 5">
            <geom name="geom obstacle 5" type="box" size="0.1590583899763615 0.17635991022710598 0.1" pos="0.47291908825508155 -1.2189465247028624 0.1" material="blue"/>
        </body>
        <body name="obstacle 6">
            <geom name="geom obstacle 6" type="box" size="0.14114535891247976 0.2190406019293031 0.1" pos="0.9751501760705845 1.0803259370228022 0.1" material="blue"/>
        </body>
        <body name="obstacle 7">
            <geom name="geom obstacle 7" type="box" size="0.12281729602645364 0.19580358313456578 0.1" pos="-0.2849898475426085 -1.120306725452612 0.1" material="blue"/>
        </body>
        <body name="obstacle 8">
            <geom name="geom obstacle 8" type="box" size="0.19767283250032522 0.22276444818224547 0.1" pos="-0.38367653339678265 -1.205966841561426 0.1" material="blue"/>
        </body>
        <body name="obstacle 9">
            <geom name="geom obstacle 9" type="box" size="0.1939757681798394 0.09714725502970684 0.1" pos="0.8954432778362293 0.8574745225532836 0.1" material="blue"/>
        </body>

    </worldbody>

    <contact>
        <exclude body1="link 0 shade" body2="link 1 shade"/>
        <exclude body1="link 0 shade" body2="link 0"/>
        <exclude body1="link 0 shade" body2="link 1"/>
        <exclude body1="link 1 shade" body2="link 0"/>
        <exclude body1="link 1 shade" body2="link 1"/>
        <exclude body1="link 0 shade" body2="obstacle 0"/>
        <exclude body1="link 0 shade" body2="obstacle 1"/>
        <exclude body1="link 0 shade" body2="obstacle 2"/>
        <exclude body1="link 0 shade" body2="obstacle 3"/>
        <exclude body1="link 0 shade" body2="obstacle 4"/>
        <exclude body1="link 0 shade" body2="obstacle 5"/>
        <exclude body1="link 0 shade" body2="obstacle 6"/>
        <exclude body1="link 0 shade" body2="obstacle 7"/>
        <exclude body1="link 0 shade" body2="obstacle 8"/>
        <exclude body1="link 0 shade" body2="obstacle 9"/>
        <exclude body1="link 1 shade" body2="obstacle 0"/>
        <exclude body1="link 1 shade" body2="obstacle 1"/>
        <exclude body1="link 1 shade" body2="obstacle 2"/>
        <exclude body1="link 1 shade" body2="obstacle 3"/>
        <exclude body1="link 1 shade" body2="obstacle 4"/>
        <exclude body1="link 1 shade" body2="obstacle 5"/>
        <exclude body1="link 1 shade" body2="obstacle 6"/>
        <exclude body1="link 1 shade" body2="obstacle 7"/>
        <exclude body1="link 1 shade" body2="obstacle 8"/>
        <exclude body1="link 1 shade" body2="obstacle 9"/>
    </contact>

    <sensor>
      <framepos objtype="site" objname="tip"/>
    </sensor>
</mujoco>
