<mujoco>
	<asset>
		<material name="red"   rgba="1 0 0 1"/>
		<material name="green" rgba="0 1 0 1"/>
		<material name="blue"  rgba="0 0 1 1"/>
		<material name="white" rgba="1 1 1 1"/>
		<material name="gray"  rgba=".5 .5 .5 1"/>
	</asset>

    <option collision="predefined"/>

    <worldbody>
        <light diffuse=".5 .5 .5" pos="0 0 10" dir="0 0 -1"/>
        <geom type="plane" size="2 2 0.1" rgba="1 1 1 1"/>

        <body name="link 0" pos="0.525 0 0.1" euler="0 90 0">
            <joint name="joint 0" type="hinge" axis="-1 0 0" pos="0 0 -0.525"/>
            <geom name="geom link 0" type="cylinder" size="0.05 0.525" material="red"/>
            <body name="link 1" pos="0 0 1.0" euler="0 0 0">
                <joint name="joint 1" type="hinge" axis="-1 0 0" pos="0 0 -0.475"/>
                <geom name="geom link 1" type="cylinder" size="0.05 0.475" material="red"/>
                <site name="tip" size="0.1" pos="0 0 0.475"/>
            </body>
        </body>

        <body name="link 0 shade" pos="0.525 0 0.1" euler="0 90 0">
            <joint name="joint 0 shade" type="hinge" axis="-1 0 0" pos="0 0 -0.525"/>
            <geom name="geom link 0 shade" type="cylinder" size="0.05 0.525" material="green"/>
            <body name="link 1 shade" pos="0 0 1.0" euler="0 0 0">
                <joint name="joint 1 shade" type="hinge" axis="-1 0 0" pos="0 0 -0.475"/>
                <geom name="geom link 1 shade" type="cylinder" size="0.05 0.475" material="green"/>
            </body>
        </body>

        <body name="obstacle 0">
            <geom name="geom obstacle 0" type="sphere" size="0.035" pos="1.09 0.0 0.1" material="blue"/>
        </body>
        <body name="obstacle 1">
            <geom name="geom obstacle 1" type="sphere" size="0.035" pos="0.5450000000000002 0.9439676901250381 0.1" material="blue"/>
        </body>
        <body name="obstacle 2">
            <geom name="geom obstacle 2" type="sphere" size="0.035" pos="-0.5449999999999998 0.9439676901250382 0.1" material="blue"/>
        </body>
        <body name="obstacle 3">
            <geom name="geom obstacle 3" type="sphere" size="0.035" pos="-1.09 1.334865011070615e-16 0.1" material="blue"/>
        </body>
        <body name="obstacle 4">
            <geom name="geom obstacle 4" type="sphere" size="0.035" pos="-0.5450000000000005 -0.9439676901250379 0.1" material="blue"/>
        </body>
        <body name="obstacle 5">
            <geom name="geom obstacle 5" type="sphere" size="0.035" pos="0.5450000000000002 -0.9439676901250381 0.1" material="blue"/>
        </body>

    </worldbody>

    <contact>
        <pair geom1="geom link 0" geom2="geom obstacle 0"/>
        <pair geom1="geom link 0" geom2="geom obstacle 1"/>
        <pair geom1="geom link 0" geom2="geom obstacle 2"/>
        <pair geom1="geom link 0" geom2="geom obstacle 3"/>
        <pair geom1="geom link 0" geom2="geom obstacle 4"/>
        <pair geom1="geom link 0" geom2="geom obstacle 5"/>
        <pair geom1="geom link 1" geom2="geom obstacle 0"/>
        <pair geom1="geom link 1" geom2="geom obstacle 1"/>
        <pair geom1="geom link 1" geom2="geom obstacle 2"/>
        <pair geom1="geom link 1" geom2="geom obstacle 3"/>
        <pair geom1="geom link 1" geom2="geom obstacle 4"/>
        <pair geom1="geom link 1" geom2="geom obstacle 5"/>
    </contact>

    <sensor>
      <framepos objtype="site" objname="tip"/>
    </sensor>
</mujoco>
