<!-- https://mujoco.readthedocs.io/en/latest/overview.html?highlight=hello.xml#examples -->

<mujoco>
	<asset>
		<material name="red"   rgba="1 0 0 1"/>
		<material name="green" rgba="0 1 0 1"/>
		<material name="blue"  rgba="0 0 1 1"/>
		<material name="white" rgba="1 1 1 1"/>
		<material name="gray"  rgba=".5 .5 .5 1"/>
	</asset>

    <option collision="predefined"/>

    <worldbody>
        <light diffuse=".5 .5 .5" pos="0 0 10" dir="0 0 -1"/>
        <geom type="plane" size="2 2 0.1" rgba="1 1 1 1"/>

        <body name="edge 0" pos="0.5 0 0.1" euler="0 90 0">
            <joint name="joint 0" type="hinge" axis="-1 0 0" pos="0 0 -0.5"/>
            <geom name="geom edge 0" type="cylinder" size="0.05 0.5" material="red"/>
            <body name="edge 1" pos="0 0 1" euler="0 0 0">
                <joint name="joint 1" type="hinge" axis="-1 0 0" pos="0 0 -0.5"/>
                <geom name="geom edge 1" type="cylinder" size="0.05 0.5" material="red"/>
                <site name="tip" size="0.1" pos="0 0 0.5"/>
            </body>
        </body>

        <body name="edge 2" pos="0.5 0 0.1" euler="0 90 0">
            <joint name="joint 2" type="hinge" axis="-1 0 0" pos="0 0 -0.5"/>
            <geom type="cylinder" size="0.05 0.5" material="green"/>
            <body name="edge 3" pos="0 0 1" euler="0 0 0">
                <joint name="joint 3" type="hinge" axis="-1 0 0" pos="0 0 -0.5"/>
                <geom type="cylinder" size="0.05 0.5" material="green"/>
            </body>
        </body>

        <body name="obstacle 0">
            <geom name="geom obstacle 0" type="box" size="0.1 0.2 0.3" pos="1.5 0.9 0.0" material="blue"/>
        </body>
        <body name="obstacle 1">
            <geom name="geom obstacle 1" type="sphere" size="0.2" pos="0.0 -1.5 0.0" material="blue"/>
        </body>

    </worldbody>

    <contact>
        <pair geom1="geom edge 0" geom2="geom obstacle 0"/>
        <pair geom1="geom edge 1" geom2="geom obstacle 0"/>
        <pair geom1="geom edge 0" geom2="geom obstacle 1"/>
        <pair geom1="geom edge 1" geom2="geom obstacle 1"/>
    </contact>

    <sensor>
      <framepos objtype="site" objname="tip"/>
    </sensor>
</mujoco>
