<mujoco>
	<asset>
		<material name="red"   rgba="1 0 0 1"/>
		<material name="green" rgba="0 1 0 1"/>
		<material name="blue"  rgba="0 0 1 1"/>
		<material name="white" rgba="1 1 1 1"/>
		<material name="gray"  rgba=".5 .5 .5 1"/>
	</asset>

    <worldbody>
        <light diffuse=".5 .5 .5" pos="0 0 10" dir="0 0 -1"/>
        <geom type="plane" size="2 2 0.1" rgba="1 1 1 1"/>

        <body name="link 0" pos="0.25 0 0.1" euler="0 90 0">
            <joint name="joint 0" type="hinge" axis="-1 0 0" pos="0 0 -0.25"/>
            <geom name="geom link 0" type="cylinder" size="0.05 0.25" material="red"/>
            <body name="link 1" pos="0 0 0.5" euler="0 0 0">
                <joint name="joint 1" type="hinge" axis="-1 0 0" pos="0 0 -0.25"/>
                <geom name="geom link 1" type="cylinder" size="0.05 0.25" material="red"/>
                <body name="link 2" pos="0 0 0.5" euler="0 0 0">
                    <joint name="joint 2" type="hinge" axis="-1 0 0" pos="0 0 -0.25"/>
                    <geom name="geom link 2" type="cylinder" size="0.05 0.25" material="red"/>
                    <body name="link 3" pos="0 0 0.5" euler="0 0 0">
                        <joint name="joint 3" type="hinge" axis="-1 0 0" pos="0 0 -0.25"/>
                        <geom name="geom link 3" type="cylinder" size="0.05 0.25" material="red"/>
                        <site name="tip" size="0.1" pos="0 0 0.25"/>
                    </body>
                </body>
            </body>
        </body>

        <body name="link 0 shade" pos="0.25 0 0.1" euler="0 90 0">
            <joint name="joint 0 shade" type="hinge" axis="-1 0 0" pos="0 0 -0.25"/>
            <geom name="geom link 0 shade" type="cylinder" size="0.05 0.25" material="green"/>
            <body name="link 1 shade" pos="0 0 0.5" euler="0 0 0">
                <joint name="joint 1 shade" type="hinge" axis="-1 0 0" pos="0 0 -0.25"/>
                <geom name="geom link 1 shade" type="cylinder" size="0.05 0.25" material="green"/>
                <body name="link 2 shade" pos="0 0 0.5" euler="0 0 0">
                    <joint name="joint 2 shade" type="hinge" axis="-1 0 0" pos="0 0 -0.25"/>
                    <geom name="geom link 2 shade" type="cylinder" size="0.05 0.25" material="green"/>
                    <body name="link 3 shade" pos="0 0 0.5" euler="0 0 0">
                        <joint name="joint 3 shade" type="hinge" axis="-1 0 0" pos="0 0 -0.25"/>
                        <geom name="geom link 3 shade" type="cylinder" size="0.05 0.25" material="green"/>
                    </body>
                </body>
            </body>
        </body>

        <body name="obstacle 0">
            <geom name="geom obstacle 0" type="box" size="0.1 0.2 0.3" pos="1.5 0.9 0.0" material="blue"/>
        </body>
        <body name="obstacle 1">
            <geom name="geom obstacle 1" type="sphere" size="0.2" pos="0.0 -1.5 0.0" material="blue"/>
        </body>
        <body name="obstacle 2">
            <geom name="geom obstacle 2" type="sphere" size="0.4" pos="-1.5 0.0 0.0" material="blue"/>
        </body>
        <body name="obstacle 3">
            <geom name="geom obstacle 3" type="box" size="0.2 0.1 0.3" pos="1.5 0.9 0.0" material="blue"/>
        </body>
        <body name="obstacle 4">
            <geom name="geom obstacle 4" type="box" size="0.1 0.2 0.3" pos="1.3 0.7 0.0" material="blue"/>
        </body>
        <body name="obstacle 5">
            <geom name="geom obstacle 5" type="sphere" size="0.2" pos="0.0 -1.4 0.0" material="blue"/>
        </body>
        <body name="obstacle 6">
            <geom name="geom obstacle 6" type="sphere" size="0.4" pos="-1.4 0.0 0.0" material="blue"/>
        </body>
        <body name="obstacle 7">
            <geom name="geom obstacle 7" type="box" size="0.2 0.1 0.3" pos="1.4 0.6 0.0" material="blue"/>
        </body>
        <body name="obstacle 8">
            <geom name="geom obstacle 8" type="box" size="0.1 0.2 0.3" pos="0.6 -0.6 0.0" material="blue"/>
        </body>
        <body name="obstacle 9">
            <geom name="geom obstacle 9" type="sphere" size="0.2" pos="-1.0 -1.0 0.0" material="blue"/>
        </body>
        <body name="obstacle 10">
            <geom name="geom obstacle 10" type="sphere" size="0.4" pos="-1.5 1.0 0.0" material="blue"/>
        </body>
        <body name="obstacle 11">
            <geom name="geom obstacle 11" type="box" size="0.2 0.1 0.3" pos="1.5 0.5 0.0" material="blue"/>
        </body>
        <body name="obstacle 12">
            <geom name="geom obstacle 12" type="box" size="0.1 0.2 0.3" pos="1.4 0.6 0.0" material="blue"/>
        </body>
        <body name="obstacle 13">
            <geom name="geom obstacle 13" type="sphere" size="0.2" pos="0.6 -0.6 0.0" material="blue"/>
        </body>
        <body name="obstacle 14">
            <geom name="geom obstacle 14" type="sphere" size="0.4" pos="-1.4 0.0 0.0" material="blue"/>
        </body>
        <body name="obstacle 15">
            <geom name="geom obstacle 15" type="box" size="0.2 0.1 0.3" pos="1.4 0.6 0.0" material="blue"/>
        </body>
        <body name="obstacle 16">
            <geom name="geom obstacle 16" type="sphere" size="0.2" pos="0.0 1.6 0.0" material="blue"/>
        </body>

    </worldbody>

    <contact>
        <exclude body1="link 0 shade" body2="link 1 shade"/>
        <exclude body1="link 1 shade" body2="link 2 shade"/>
        <exclude body1="link 2 shade" body2="link 3 shade"/>
        <exclude body1="link 0 shade" body2="link 0"/>
        <exclude body1="link 0 shade" body2="link 1"/>
        <exclude body1="link 0 shade" body2="link 2"/>
        <exclude body1="link 0 shade" body2="link 3"/>
        <exclude body1="link 1 shade" body2="link 0"/>
        <exclude body1="link 1 shade" body2="link 1"/>
        <exclude body1="link 1 shade" body2="link 2"/>
        <exclude body1="link 1 shade" body2="link 3"/>
        <exclude body1="link 2 shade" body2="link 0"/>
        <exclude body1="link 2 shade" body2="link 1"/>
        <exclude body1="link 2 shade" body2="link 2"/>
        <exclude body1="link 2 shade" body2="link 3"/>
        <exclude body1="link 3 shade" body2="link 0"/>
        <exclude body1="link 3 shade" body2="link 1"/>
        <exclude body1="link 3 shade" body2="link 2"/>
        <exclude body1="link 3 shade" body2="link 3"/>
        <exclude body1="link 0 shade" body2="obstacle 0"/>
        <exclude body1="link 0 shade" body2="obstacle 1"/>
        <exclude body1="link 0 shade" body2="obstacle 2"/>
        <exclude body1="link 0 shade" body2="obstacle 3"/>
        <exclude body1="link 0 shade" body2="obstacle 4"/>
        <exclude body1="link 0 shade" body2="obstacle 5"/>
        <exclude body1="link 0 shade" body2="obstacle 6"/>
        <exclude body1="link 0 shade" body2="obstacle 7"/>
        <exclude body1="link 0 shade" body2="obstacle 8"/>
        <exclude body1="link 0 shade" body2="obstacle 9"/>
        <exclude body1="link 0 shade" body2="obstacle 10"/>
        <exclude body1="link 0 shade" body2="obstacle 11"/>
        <exclude body1="link 0 shade" body2="obstacle 12"/>
        <exclude body1="link 0 shade" body2="obstacle 13"/>
        <exclude body1="link 0 shade" body2="obstacle 14"/>
        <exclude body1="link 0 shade" body2="obstacle 15"/>
        <exclude body1="link 0 shade" body2="obstacle 16"/>
        <exclude body1="link 1 shade" body2="obstacle 0"/>
        <exclude body1="link 1 shade" body2="obstacle 1"/>
        <exclude body1="link 1 shade" body2="obstacle 2"/>
        <exclude body1="link 1 shade" body2="obstacle 3"/>
        <exclude body1="link 1 shade" body2="obstacle 4"/>
        <exclude body1="link 1 shade" body2="obstacle 5"/>
        <exclude body1="link 1 shade" body2="obstacle 6"/>
        <exclude body1="link 1 shade" body2="obstacle 7"/>
        <exclude body1="link 1 shade" body2="obstacle 8"/>
        <exclude body1="link 1 shade" body2="obstacle 9"/>
        <exclude body1="link 1 shade" body2="obstacle 10"/>
        <exclude body1="link 1 shade" body2="obstacle 11"/>
        <exclude body1="link 1 shade" body2="obstacle 12"/>
        <exclude body1="link 1 shade" body2="obstacle 13"/>
        <exclude body1="link 1 shade" body2="obstacle 14"/>
        <exclude body1="link 1 shade" body2="obstacle 15"/>
        <exclude body1="link 1 shade" body2="obstacle 16"/>
        <exclude body1="link 2 shade" body2="obstacle 0"/>
        <exclude body1="link 2 shade" body2="obstacle 1"/>
        <exclude body1="link 2 shade" body2="obstacle 2"/>
        <exclude body1="link 2 shade" body2="obstacle 3"/>
        <exclude body1="link 2 shade" body2="obstacle 4"/>
        <exclude body1="link 2 shade" body2="obstacle 5"/>
        <exclude body1="link 2 shade" body2="obstacle 6"/>
        <exclude body1="link 2 shade" body2="obstacle 7"/>
        <exclude body1="link 2 shade" body2="obstacle 8"/>
        <exclude body1="link 2 shade" body2="obstacle 9"/>
        <exclude body1="link 2 shade" body2="obstacle 10"/>
        <exclude body1="link 2 shade" body2="obstacle 11"/>
        <exclude body1="link 2 shade" body2="obstacle 12"/>
        <exclude body1="link 2 shade" body2="obstacle 13"/>
        <exclude body1="link 2 shade" body2="obstacle 14"/>
        <exclude body1="link 2 shade" body2="obstacle 15"/>
        <exclude body1="link 2 shade" body2="obstacle 16"/>
        <exclude body1="link 3 shade" body2="obstacle 0"/>
        <exclude body1="link 3 shade" body2="obstacle 1"/>
        <exclude body1="link 3 shade" body2="obstacle 2"/>
        <exclude body1="link 3 shade" body2="obstacle 3"/>
        <exclude body1="link 3 shade" body2="obstacle 4"/>
        <exclude body1="link 3 shade" body2="obstacle 5"/>
        <exclude body1="link 3 shade" body2="obstacle 6"/>
        <exclude body1="link 3 shade" body2="obstacle 7"/>
        <exclude body1="link 3 shade" body2="obstacle 8"/>
        <exclude body1="link 3 shade" body2="obstacle 9"/>
        <exclude body1="link 3 shade" body2="obstacle 10"/>
        <exclude body1="link 3 shade" body2="obstacle 11"/>
        <exclude body1="link 3 shade" body2="obstacle 12"/>
        <exclude body1="link 3 shade" body2="obstacle 13"/>
        <exclude body1="link 3 shade" body2="obstacle 14"/>
        <exclude body1="link 3 shade" body2="obstacle 15"/>
        <exclude body1="link 3 shade" body2="obstacle 16"/>
    </contact>

    <sensor>
      <framepos objtype="site" objname="tip"/>
    </sensor>
</mujoco>
