<mujoco>
	<asset>
		<material name="red"   rgba="1 0 0 1"/>
		<material name="green" rgba="0 1 0 1"/>
		<material name="blue"  rgba="0 0 1 1"/>
		<material name="white" rgba="1 1 1 1"/>
		<material name="gray"  rgba=".5 .5 .5 1"/>
	</asset>

    <worldbody>
        <light diffuse=".5 .5 .5" pos="0 0 10" dir="0 0 -1"/>
        <geom type="plane" size="4 3 0.1" rgba="1 1 1 1"/>

        <body name="link 0-0" pos="-0.5 0 0.1" euler="0 90 0">
            <joint name="joint 0-0" type="hinge" axis="-1 0 0" pos="0 0 -0.5"/>
            <geom name="geom link 0-0" type="cylinder" size="0.05 0.5" material="red"/>
            <body name="link 0-1" pos="0 0 1.0" euler="0 0 0">
                <joint name="joint 0-1" type="hinge" axis="-1 0 0" pos="0 0 -0.5"/>
                <geom name="geom link 0-1" type="cylinder" size="0.05 0.5" material="red"/>
            </body>
        </body>

        <body name="link 1-0" pos="1.5 0 0.1" euler="0 90 0">
            <joint name="joint 1-0" type="hinge" axis="-1 0 0" pos="0 0 -0.5"/>
            <geom name="geom link 1-0" type="cylinder" size="0.05 0.5" material="red"/>
            <body name="link 1-1" pos="0 0 1.0" euler="0 0 0">
                <joint name="joint 1-1" type="hinge" axis="-1 0 0" pos="0 0 -0.5"/>
                <geom name="geom link 1-1" type="cylinder" size="0.05 0.5" material="red"/>
            </body>
        </body>


        <body name="link 0-0 shade" pos="-0.5 0 0.1" euler="0 90 0">
            <joint name="joint 0-0 shade" type="hinge" axis="-1 0 0" pos="0 0 -0.5"/>
            <geom name="geom link 0-0 shade" type="cylinder" size="0.02 0.5" material="green" contype="0" conaffinity="0" />
            <body name="link 0-1 shade" pos="0 0 1.0" euler="0 0 0">
                <joint name="joint 0-1 shade" type="hinge" axis="-1 0 0" pos="0 0 -0.5"/>
                <geom name="geom link 0-1 shade" type="cylinder" size="0.02 0.5" material="green" contype="0" conaffinity="0" />
            </body>
        </body>

        <body name="link 1-0 shade" pos="1.5 0 0.1" euler="0 90 0">
            <joint name="joint 1-0 shade" type="hinge" axis="-1 0 0" pos="0 0 -0.5"/>
            <geom name="geom link 1-0 shade" type="cylinder" size="0.02 0.5" material="green" contype="0" conaffinity="0" />
            <body name="link 1-1 shade" pos="0 0 1.0" euler="0 0 0">
                <joint name="joint 1-1 shade" type="hinge" axis="-1 0 0" pos="0 0 -0.5"/>
                <geom name="geom link 1-1 shade" type="cylinder" size="0.02 0.5" material="green" contype="0" conaffinity="0" />
            </body>
        </body>

        <body name="sudo sphere">
            <geom name="sudo sphere 1" type="sphere" size="0.1" pos="0.0 0.0 -100.0" contype="0" conaffinity="0"  material="blue"/>
        </body>

    </worldbody>
</mujoco>
